Workbook

Sheet ESAU Calculator
B2: ESAU Calculator (SIS/ APB/ TPCE)
B4: Name | C4: RM Category | D4: Joining Date | E4: Performance Period | H4: HR AGE (Month)
E5: Start | F5: End | G5: Month
B6: Mr. ABCD | C6: TPCE | D6: 44621 | E6: 45292 | F6: 45351 | G6: =IF(IFERROR(IF(OR(E6="",F6=""),"N/A",IF(AND(D6>E6,DAY(D6)=1),DATEDIF(D6+1,F6+1,"M"),IF(AND(D6>E6,DAY(D6)<>1),DATEDIF(D6,F6+1,"M"),DATEDIF(E6,F6+1,"M")))),"N/A")=0,"N/A",IFERROR(IF(OR(E6="",F6=""),"N/A",IF(AND(D6>E6,DAY(D6)=1),DATEDIF(D6+1,F6+1,"M"),IF(AND(D6>E6,DAY(D6)<>1),DATEDIF(D6,F6+1,"M"),DATEDIF(E6,F6+1,"M")))),"N/A")) -> 2 | H6: =IF(OR(D6>F6,F6=""),"-",(DATEDIF(D6,F6+1,"M"))) -> 24
B9: Particulars | D9: Point | E9: Total Points | F9: Grade | J9: Quarterly Result | K9: Total Point
B10: Disbursement Target | C10: 100 | D10: =IF($C$6="SIS",(IF($H6<=12,IFERROR((IF(OR($C12=0,$C12=""),0,IF(AND($C12>=CCT!$B$21,$C12<CCT!$C$21),CCT!$F$21+(CCT!$G$21-CCT!$F$21)/(CCT!$C$21-CCT!$B$21)*($C12-CCT!$B$21),IF(AND($C12>=CCT!$B$20,$C12<CCT!$C$20),CCT!$F$20+(CCT!$G$20-CCT!$F$20)/(CCT!$C$20-CCT!$B$20)*($C12-CCT!$B$20),IF(AND($C12>=CCT!$B$19,$C12<CCT!$C$19),CCT!$F$19+(CCT!$G$19-CCT!$F$19)/(CCT!$C$19-CCT!$B$19)*($C12-CCT!$B$19),IF(AND($C12>=CCT!$B$18,$C12<CCT!$C$18),CCT!$F$18+(CCT!$G$18-CCT!$F$18)/(CCT!$C$18-CCT!$B$18)*($C12-CCT!$B$18),IF($C12>=CCT!$C$18,CCT!$G$18,0))))))),0),IFERROR((IF(OR($C12=0,$C12=""),0,IF(AND($C12>=CCT!$B$21,$C12<CCT!$C$21),CCT!$D$21+(CCT!$E$21-CCT!$D$21)/(CCT!$C$21-CCT!$B$21)*($C12-CCT!$B$21),IF(AND($C12>=CCT!$B$20,$C12<CCT!$C$20),CCT!$D$20+(CCT!$E$20-CCT!$D$20)/(CCT!$C$20-CCT!$B$20)*($C12-CCT!$B$20),IF(AND($C12>=CCT!$B$19,$C12<CCT!$C$19),CCT!$D$19+(CCT!$E$19-CCT!$D$19)/(CCT!$C$19-CCT!$B$19)*($C12-CCT!$B$19),IF(AND($C12>=CCT!$B$18,$C12<CCT!$C$18),CCT!$D$18+(CCT!$E$18-CCT!$D$18)/(CCT!$C$18-CCT!$B$18)*($C12-CCT!$B$18),IF($C12>=CCT!$C$18,CCT!$E$18,0))))))),0))),IF($C$6="APB",(IF($H6<=12,IFERROR((IF(OR($C12=0,$C12=""),0,IF(AND($C12>=CCT!$T$21,$C12<CCT!$U$21),CCT!$X$21+(CCT!$Y$21-CCT!$X$21)/(CCT!$U$21-CCT!$T$21)*($C12-CCT!$T$21),IF(AND($C12>=CCT!$T$20,$C12<CCT!$U$20),CCT!$X$20+(CCT!$Y$20-CCT!$X$20)/(CCT!$U$20-CCT!$T$20)*($C12-CCT!$T$20),IF(AND($C12>=CCT!$T$19,$C12<CCT!$U$19),CCT!$X$19+(CCT!$Y$19-CCT!$X$19)/(CCT!$U$19-CCT!$T$19)*($C12-CCT!$T$19),IF(AND($C12>=CCT!$T$18,$C12<CCT!$U$18),CCT!$X$18+(CCT!$Y$18-CCT!$X$18)/(CCT!$U$18-CCT!$T$18)*($C12-CCT!$T$18),IF($C12>=CCT!$U$18,CCT!$Y$18,0))))))),0),IFERROR((IF(OR($C12=0,$C12=""),0,IF(AND($C12>=CCT!$T$21,$C12<CCT!$U$21),CCT!$V$21+(CCT!$W$21-CCT!$V$21)/(CCT!$U$21-CCT!$T$21)*($C12-CCT!$T$21),IF(AND($C12>=CCT!$T$20,$C12<CCT!$U$20),CCT!$V$20+(CCT!$W$20-CCT!$V$20)/(CCT!$U$20-CCT!$T$20)*($C12-CCT!$T$20),IF(AND($C12>=CCT!$T$19,$C12<CCT!$U$19),CCT!$V$19+(CCT!$W$19-CCT!$V$19)/(CCT!$U$19-CCT!$T$19)*($C12-CCT!$T$19),IF(AND($C12>=CCT!$T$18,$C12<CCT!$U$18),CCT!$V$18+(CCT!$W$18-CCT!$V$18)/(CCT!$U$18-CCT!$T$18)*($C12-CCT!$T$18),IF($C12>=CCT!$U$18,CCT!$W$18,0))))))),0))),IF($C$6="TPCE",(IF($H6<=12,IFERROR((IF(OR($C12=0,$C12=""),0,IF(AND($C12>=CCT!$K$21,$C12<CCT!$L$21),CCT!$O$21+(CCT!$P$21-CCT!$O$21)/(CCT!$L$21-CCT!$K$21)*($C12-CCT!$K$21),IF(AND($C12>=CCT!$K$20,$C12<CCT!$L$20),CCT!$O$20+(CCT!$P$20-CCT!$O$20)/(CCT!$L$20-CCT!$K$20)*($C12-CCT!$K$20),IF(AND($C12>=CCT!$K$19,$C12<CCT!$L$19),CCT!$O$19+(CCT!$P$19-CCT!$O$19)/(CCT!$L$19-CCT!$K$19)*($C12-CCT!$K$19),IF(AND($C12>=CCT!$K$18,$C12<CCT!$L$18),CCT!$O$18+(CCT!$P$18-CCT!$O$18)/(CCT!$L$18-CCT!$K$18)*($C12-CCT!$K$18),IF($C12>=CCT!$L$18,CCT!$P$18,0))))))),0),IFERROR((IF(OR($C12=0,$C12=""),0,IF(AND($C12>=CCT!$K$21,$C12<CCT!$L$21),CCT!$M$21+(CCT!$N$21-CCT!$M$21)/(CCT!$L$21-CCT!$K$21)*($C12-CCT!$K$21),IF(AND($C12>=CCT!$K$20,$C12<CCT!$L$20),CCT!$M$20+(CCT!$N$20-CCT!$M$20)/(CCT!$L$20-CCT!$K$20)*($C12-CCT!$K$20),IF(AND($C12>=CCT!$K$19,$C12<CCT!$L$19),CCT!$M$19+(CCT!$N$19-CCT!$M$19)/(CCT!$L$19-CCT!$K$19)*($C12-CCT!$K$19),IF(AND($C12>=CCT!$K$18,$C12<CCT!$L$18),CCT!$M$18+(CCT!$N$18-CCT!$M$18)/(CCT!$L$18-CCT!$K$18)*($C12-CCT!$K$18),IF($C12>=CCT!$L$18,CCT!$N$18,0))))))),0))),0))) -> 80 | E10: =SUM(D10:D15) -> 90 | F10: =INDEX(CCT!$B$5:$B$8,MATCH(F11,CCT!$C$5:$C$8,0)) -> Standard | J10: Quarter… | K10: 100
B11: Net Disbursement Ex. RSTL | C11: 150 | F11: =IF(OR($G6="N/A",$G6=0),"N/A",IF(AND(E10>CCT!$D$5,E10<=CCT!$E$5),CCT!$C$5,IF(AND(E10>CCT!$D$6,E10<=CCT!$E$6),CCT!$C$6,IF(AND(E10>CCT!$D$7,E10<=CCT!$E$7),CCT!$C$7,IF(AND(E10>=CCT!$D$8,E10<=CCT!$E$8),CCT!$C$8,"N/A"))))) -> S | J11: Quarter… | K11: 80
B12: Achievement % | C12: =IFERROR(C11/C10,0) -> 1.5 | J12: Quarter…
B13: Number of File Disbursed | C13: 4 | D13: =IF($C$6="SIS",(IFERROR(IF(AND(H6<=12,C13/G6>=CCT!$F$31),CCT!$G$31,IF(AND(H6<=12,C13/G6<CCT!$F$31),(CCT!$G$31/CCT!$F$31)*(C13/G6),IF(AND(H6>12,C13/G6>=CCT!$D$31),CCT!$E$31,IF(AND(H6>12,C13/G6<CCT!$D$31),(CCT!$E$31/CCT!$D$31)*(C13/G6),"?")))),0)),IF($C$6="APB",(IFERROR(IF(AND(H6<=12,C13/G6>=CCT!$X$31),CCT!$Y$31,IF(AND(H6<=12,C13/G6<CCT!$X$31),(CCT!$Y$31/CCT!$X$31)*(C13/G6),IF(AND(H6>12,C13/G6>=CCT!$V$31),CCT!$W$31,IF(AND(H6>12,C13/G6<CCT!$V$31),(CCT!$W$31/CCT!$V$31)*(C13/G6),"?")))),0)),IF($C$6="TPCE",(IFERROR(IF(AND(H6<=12,C13/G6>=CCT!$O$31),CCT!$P$31,IF(AND(H6<=12,C13/G6<CCT!$O$31),(CCT!$P$31/CCT!$O$31)*(C13/G6),IF(AND(H6>12,C13/G6>=CCT!$M$31),CCT!$N$31,IF(AND(H6>12,C13/G6<CCT!$M$31),(CCT!$N$31/CCT!$M$31)*(C13/G6),"?")))),0)),0))) -> 10 | J13: Quarter…
B14: Portfolio | C14: 10 | D14: =IF($C$6="SIS",(IF(C14=0,0,IF(AND(H6<=12,C15<=CCT!$F$25),CCT!$G$25,IF(AND(H6<=12,C15>0),CCT!$G$26,IF(AND(H6>12,C15<=CCT!$D$25),CCT!$E$25,IF(AND(H6>12,C15>=CCT!$D$26),CCT!$E$26,IF(AND(H6>12,C15>CCT!$D$25),((CCT!$D$26-C15)/(CCT!$D$26-CCT!$D$25)*CCT!$E$25),"?"))))))),IF($C$6="APB",(IF(C14=0,0,IF(AND(H6<=12,C15<=CCT!$X$25),CCT!$Y$25,IF(AND(H6<=12,C15>0),CCT!$Y$26,IF(AND(H6>12,C15<=CCT!$V$25),CCT!$W$25,IF(AND(H6>12,C15>=CCT!$V$26),CCT!$W$26,IF(AND(H6>12,C15>CCT!$V$25),((CCT!$V$26-C15)/(CCT!$V$26-CCT!$V$25)*CCT!$W$25),"?"))))))),IF($C$6="TPCE",IF(OR($C14=0,$H6="-"),0,IF(AND($H6<=12,$C15<=CCT!$O$25),CCT!$P$25,IF(AND($H6<=12,$C15>0),CCT!$P$26,IF(AND($H6>12,$C15<=CCT!$M$25),CCT!$N$25,IF(AND($H6>12,$C15>CCT!$M$26),CCT!$N$26,"?"))))),0))) -> 0 | J14: Total Point | K14: =SUM(K10:K13) -> 180
B15: X DPD PAR / 90 DPD PAR (APB) | C15: 0.01 | F15: =INDEX(CCT!$B$5:$B$8,MATCH(F11,CCT!$C$5:$C$8,0)) -> Standard | J15: Average Point | K15: =IFERROR(K14/COUNTIFS($K$10:$K$13,">=0"),"0.00") -> 90
J16: Final Grade | K16: =IF(AND(K15>CCT!$D$5,K15<=CCT!$E$5),CCT!$C$5,IF(AND(K15>CCT!$D$6,K15<=CCT!$E$6),CCT!$C$6,IF(AND(K15>CCT!$D$7,K15<=CCT!$E$7),CCT!$C$7,IF(AND(K15>=CCT!$D$8,K15<=CCT!$E$8),CCT!$C$8,"N/A")))) -> S
B17: Please provide/ select data in the Yellow-marked cells

Sheet CCT
B1: Criteria (Sales-SIS) | J1: * | K1: Criteria (TPCE) | S1: * | T1: Criteria (Sales-APB) | AD1: Start | AE1: End | AG1: Branch
J2: * | S2: * | AD2: 45292 | AE2: =EOMONTH(AD2,0) -> 45322 | AG2: SME | AH2: SEF
B3: GRADE | D3: Point Range | J3: * | K3: GRADE | M3: Point Range | S3: * | T3: GRADE | V3: Point Range | AD3: =EDATE(AD2,1) -> 45323 | AE3: =EOMONTH(AD3,0) -> 45351 | AG3: Agrabad
D4: > | E4: <= | J4: * | M4: > | N4: <= | S4: * | V4: > | W4: <= | AD4: =EDATE(AD3,1) -> 45352 | AE4: =EOMONTH(AD4,0) -> 45382 | AG4: Barisal
B5: Excellent | C5: E | D5: 95 | E5: 100 | J5: * | K5: Excellent | L5: E | M5: 95 | N5: 100 | S5: * | T5: Excellent | U5: E | V5: 95 | W5: 100 | AD5: =EDATE(AD4,1) -> 45383 | AE5: =EOMONTH(AD5,0) -> 45412 | AG5: Bhulta
B6: Standard | C6: S | D6: 80 | E6: =D5 -> 95 | J6: * | K6: Standard | L6: S | M6: 80 | N6: =M5 -> 95 | S6: * | T6: Standard | U6: S | V6: 80 | W6: =V5 -> 95 | AD6: =EDATE(AD5,1) -> 45413 | AE6: =EOMONTH(AD6,0) -> 45443 | AG6: Bogra
B7: Average | C7: A | D7: 60 | E7: =D6 -> 80 | J7: * | K7: Average | L7: A | M7: 60 | N7: =M6 -> 80 | S7: * | T7: Average | U7: A | V7: 60 | W7: =V6 -> 80 | AD7: =EDATE(AD6,1) -> 45444 | AE7: =EOMONTH(AD7,0) -> 45473 | AG7: Chowmuhani
B8: Unsatisfactory | C8: U | D8: -100 | E8: =D7 -> 60 | J8: * | K8: Unsatisfactory | L8: U | M8: -100 | N8: =M7 -> 60 | S8: * | T8: Unsatisfactory | U8: U | V8: -100 | W8: =V7 -> 60 | AD8: =EDATE(AD7,1) -> 45474 | AE8: =EOMONTH(AD8,0) -> 45504 | AG8: Comilla
J9: * | S9: * | AD9: =EDATE(AD8,1) -> 45505 | AE9: =EOMONTH(AD9,0) -> 45535 | AG9: Dilkusha
B10: Service Length wise Point Distribution | D10: Age > 1 year | E10: Age <= 1 year | J10: * | K10: Service Length wise Point Distribution | M10: Age > 1 year | N10: Age <= 1 year | S10: * | T10: Service Length wise Point Distribution | V10: Age > 1 year | W10: Age <= 1 year | AD10: =EDATE(AD9,1) -> 45536 | AE10: =EOMONTH(AD10,0) -> 45565 | AG10: Dinajpur
B11: Net Disbursement | D11: 60 | E11: 70 | J11: * | K11: Net Disbursement | M11: 80 | N11: 80 | S11: * | T11: Net Disbursement | V11: 60 | W11: 70 | AD11: =EDATE(AD10,1) -> 45566 | AE11: =EOMONTH(AD11,0) -> 45596 | AG11: Elephant Road
B12: No of File | D12: 20 | E12: 30 | J12: * | K12: No of File | M12: 20 | N12: 20 | S12: * | T12: No of File | V12: 20 | W12: 30 | AD12: =EDATE(AD11,1) -> 45597 | AE12: =EOMONTH(AD12,0) -> 45626 | AG12: Faridpur
B13: X DPD PAR | D13: 20 | E13: -5 | J13: * | K13: X DPD PAR | M13: -5 | N13: -5 | S13: * | T13: 90 DPD PAR | V13: 20 | W13: -5 | AD13: =EDATE(AD12,1) -> 45627 | AE13: =EOMONTH(AD13,0) -> 45657 | AG13: Gazipur
B14: Total | D14: =SUM(D11:D13) -> 100 | E14: =E11+E12 -> 100 | J14: * | K14: Total | M14: =M11+M12 -> 100 | N14: =N11+N12 -> 100 | S14: * | T14: Total | V14: =SUM(V11:V13) -> 100 | W14: =W11+W12 -> 100 | AD14: =EDATE(AD13,1) -> 45658 | AE14: =EOMONTH(AD14,0) -> 45688 | AG14: Gulshan
J15: * | S15: * | AD15: =EDATE(AD14,1) -> 45689 | AE15: =EOMONTH(AD15,0) -> 45716 | AG15: Hobiganj
B16: Disbursement Achievement | D16: Point [ > 1 Year ] | F16: Point [ <= 1 Year ] | J16: * | K16: Disbursement Achievement | M16: Point [ > 1 Year ] | O16: Point [ <= 1 Year ] | S16: * | T16: Disbursement Achievement | V16: Point [ > 1 Year ] | X16: Point [ <= 1 Year ] | AD16: =EDATE(AD15,1) -> 45717 | AE16: =EOMONTH(AD16,0) -> 45747 | AG16: Imamganj
B17: >= | C17: < | D17: Start | E17: End | F17: Start | G17: End | J17: * | K17: >= | L17: < | M17: Start | N17: End | O17: Start | P17: End | S17: * | T17: >= | U17: < | V17: Start | W17: End | X17: Start | Y17: End | AD17: =EDATE(AD16,1) -> 45748 | AE17: =EOMONTH(AD17,0) -> 45777 | AG17: Jessore
B18: 1.5 | C18: 1000 | D18: =D11 -> 60 | E18: =D11 -> 60 | F18: =E11 -> 70 | G18: =E11 -> 70 | J18: * | K18: 1.3 | L18: 1000 | M18: =M11 -> 80 | N18: =M11 -> 80 | O18: =N11 -> 80 | P18: =N11 -> 80 | S18: * | T18: 1.5 | U18: 1000 | V18: =V11 -> 60 | W18: =V11 -> 60 | X18: =W11 -> 70 | Y18: =W11 -> 70 | AD18: =EDATE(AD17,1) -> 45778 | AE18: =EOMONTH(AD18,0) -> 45808 | AG18: Keranigonj
B19: 1.25 | C19: =B18 -> 1.5 | D19: 55 | E19: =D18-0.01 -> 59.99 | F19: 65 | G19: =F18-0.01 -> 69.99 | J19: * | K19: 1.1 | L19: =K18 -> 1.3 | M19: =F19+10 -> 75 | N19: =M18-0.01 -> 79.99 | O19: 75 | P19: =O18-0.01 -> 79.99 | S19: * | T19: 1.25 | U19: =T18 -> 1.5 | V19: 55 | W19: =V18-0.01 -> 59.99 | X19: 65 | Y19: =X18-0.01 -> 69.99 | AD19: =EDATE(AD18,1) -> 45809 | AE19: =EOMONTH(AD19,0) -> 45838 | AG19: Khulna
B20: 1 | C20: =B19 -> 1.25 | D20: 50 | E20: =D19-0.01 -> 54.99 | F20: 60 | G20: =F19-0.01 -> 64.99 | J20: * | K20: 0.9 | L20: =K19 -> 1.1 | M20: =F20+10 -> 70 | N20: =M19-0.01 -> 74.99 | O20: 70 | P20: =O19-0.01 -> 74.99 | S20: * | T20: 1 | U20: =T19 -> 1.25 | V20: 50 | W20: =V19-0.01 -> 54.99 | X20: 60 | Y20: =X19-0.01 -> 64.99 | AD20: =EDATE(AD19,1) -> 45839 | AE20: =EOMONTH(AD20,0) -> 45869 | AG20: Kushtia
B21: 0 | C21: =B20 -> 1 | D21: 0.01 | E21: =D20-0.01 -> 49.99 | F21: 0.01 | G21: =F20-0.01 -> 59.99 | J21: * | K21: 0 | L21: =K20 -> 0.9 | M21: 0.01 | N21: =M20-0.01 -> 69.99 | O21: 0.01 | P21: =O20-0.01 -> 69.99 | S21: * | T21: 0 | U21: =T20 -> 1 | V21: 0.01 | W21: =V20-0.01 -> 49.99 | X21: 0.01 | Y21: =X20-0.01 -> 59.99 | AD21: =EDATE(AD20,1) -> 45870 | AE21: =EOMONTH(AD21,0) -> 45900 | AG21: Mirpur
J22: * | S22: * | AD22: =EDATE(AD21,1) -> 45901 | AE22: =EOMONTH(AD22,0) -> 45930 | AG22: Mymensingh
B23: Initiating PAR | D23: Age > 1 year | F23: Age <= 1 year | J23: * | K23: Initiating PAR | M23: Age > 1 year | O23: Age <= 1 year | S23: * | T23: Initiating PAR | V23: Age > 1 year | X23: Age <= 1 year | AD23: =EDATE(AD22,1) -> 45931 | AE23: =EOMONTH(AD23,0) -> 45961 | AG23: Nandankanon
D24: Benchmark | E24: Point | F24: Benchmark | G24: Point | J24: * | M24: Benchmark | N24: Point | O24: Benchmark | P24: Point | S24: * | V24: Benchmark | W24: Point | X24: Benchmark | Y24: Point | AD24: =EDATE(AD23,1) -> 45962 | AE24: =EOMONTH(AD24,0) -> 45991 | AG24: Narayangonj
B25: Initiating PAR <= | D25: 0.01 | E25: =D13 -> 20 | F25: 0 | G25: 0 | J25: * | K25: Initiating PAR <= | M25: 0.03 | N25: 0 | O25: 0 | P25: 0 | S25: * | T25: Initiating PAR <= | V25: 0.03 | W25: =V13 -> 20 | X25: 0 | Y25: 0 | AD25: =EDATE(AD24,1) -> 45992 | AE25: =EOMONTH(AD25,0) -> 46022 | AG25: Narsingdi
B26: Initiating PAR >= | D26: 0.1 | E26: 0 | F26: 0 | G26: -5 | J26: * | K26: Initiating PAR > | M26: 0.03 | N26: -5 | O26: 0 | P26: -5 | S26: * | T26: Initiating PAR >= | V26: 0.15 | W26: 0 | X26: 0 | Y26: -5 | AD26: =EDATE(AD25,1) -> 46023 | AE26: =EOMONTH(AD26,0) -> 46053 | AG26: Natore
B27: Initiating PAR | D27: > 1.00% to < 10.00% | E27: Pro Rata Basis | J27: * | K27: Initiating PAR | M27: > 1.00% to < 10.00% | N27: Pro Rata Basis | S27: * | T27: Initiating PAR | V27: > 3.00% to < 15.00% | W27: Pro Rata Basis | AD27: =EDATE(AD26,1) -> 46054 | AE27: =EOMONTH(AD27,0) -> 46081 | AG27: Rajshahi
J28: * | S28: * | AD28: =EDATE(AD27,1) -> 46082 | AE28: =EOMONTH(AD28,0) -> 46112 | AG28: Rangpur
B29: Number of File Disbursed (Excluding RSTL and Duplicate AC) | D29: Age > 1 year | F29: Age <= 1 year | J29: * | K29: Number of File Disbursed (Excluding RSTL and Duplicate AC) | M29: Age > 1 year | O29: Age <= 1 year | S29: * | T29: Number of File Disbursed (Excluding RSTL and Duplicate AC) | V29: Age > 1 year | X29: Age <= 1 year | AD29: =EDATE(AD28,1) -> 46113 | AE29: =EOMONTH(AD29,0) -> 46142 | AG29: Savar
D30: File | E30: Point | F30: File | G30: Point | J30: * | M30: File | N30: Point | O30: File | P30: Point | S30: * | V30: File | W30: Point | X30: File | Y30: Point | AD30: =EDATE(AD29,1) -> 46143 | AE30: =EOMONTH(AD30,0) -> 46173 | AG30: Sylhet
B31: Avg. file per Month >= | D31: 4 | E31: =D12 -> 20 | F31: 3 | G31: =E12 -> 30 | J31: * | K31: Avg. file per Month >= | M31: 4 | N31: =M12 -> 20 | O31: 3 | P31: =N12 -> 20 | S31: * | T31: Avg. file per Month >= | V31: 2.5 | W31: =V12 -> 20 | X31: 3 | Y31: =W12 -> 30 | AD31: =EDATE(AD30,1) -> 46174 | AE31: =EOMONTH(AD31,0) -> 46203 | AG31: Tongi
B32: Avg. file per Month < | D32: 4 | E32: Pro Rata | F32: 3 | G32: Pro Rata | J32: * | K32: Avg. file per Month < | M32: 4 | N32: Pro Rata | O32: 3 | P32: Pro Rata | S32: * | T32: Avg. file per Month < | V32: 2.5 | W32: Pro Rata | X32: 3 | Y32: Pro Rata | AD32: =EDATE(AD31,1) -> 46204 | AE32: =EOMONTH(AD32,0) -> 46234
J33: * | S33: * | AD33: =EDATE(AD32,1) -> 46235 | AE33: =EOMONTH(AD33,0) -> 46265
J34: * | S34: * | AD34: =EDATE(AD33,1) -> 46266 | AE34: =EOMONTH(AD34,0) -> 46295
B35: Designation | C35: Monthly Target | J35: * | S35: * | AD35: =EDATE(AD34,1) -> 46296 | AE35: =EOMONTH(AD35,0) -> 46326
B36: ATO | D36: ATO | J36: * | S36: * | AD36: =EDATE(AD35,1) -> 46327 | AE36: =EOMONTH(AD36,0) -> 46356
B37: TO | D37: TO | J37: * | S37: * | AD37: =EDATE(AD36,1) -> 46357 | AE37: =EOMONTH(AD37,0) -> 46387
B38: STO | D38: STO | J38: * | S38: * | AD38: =EDATE(AD37,1) -> 46388 | AE38: =EOMONTH(AD38,0) -> 46418
B39: Officer Grade – I | D39: JO | J39: * | S39: * | AD39: =EDATE(AD38,1) -> 46419 | AE39: =EOMONTH(AD39,0) -> 46446
B40: Officer Grade – II | D40: AO | J40: * | S40: * | AD40: =EDATE(AD39,1) -> 46447 | AE40: =EOMONTH(AD40,0) -> 46477
...
